Workbook

Sheet garden_data
A1: Garden Inventory
A5: House ID | B5: P11 | C5: TIME AND DATE START RECORDING
A6: ARU ID
A7: Garden width and length (m) | B7: 6*10.6 - (3.1*2.5)
C9: Cover %
A10: Grass strata | B10: TRUE | C10: 40
A11: Herbaceous strata | B11: TRUE | C11: 50
A12: Shrub strata | B12: TRUE | C12: 10
A13: Tree strata | B13: TRUE | C13: 10
A14: Notes
A16: Shrub species | B16: Family | C16: Shrub cover % | D16: Native or non-native | E16: Notes | F16: Plant species | G16: Family | H16: Plant cover % | I16: Native or non-native
A17: Juniperus comunis | B17: Cupresaceae | D17: non-native | E17: Hedge | F17: Rutabaga | H17: 5 | I17: non-native
A18: Ilex | D18: non-native | E18: Hedge | F18: Leek | H18: 1 | I18: non-native
A19: Chamaecyparis | D19: non-native | E19: Hedge | F19: Bok choy | H19: 1 | I19: non-native
F20: Garlic | H20: 10 | I20: non-native
F21: English Holly | H21: 1 | I21: non-native
A25: Hedge
A26: Hedge species | B26: Family | C26: Height
A27: Juniperus comunis | B27: Cupressaceae | C27: 45721
A28: Ilex aquifolium | B28: Aquifoliaceae | C28: 45664
A29: Chamaecyparis | B29: Cupressaceae | C29: 45719
A31: House ID | B31: P12 | C31: TIME AND DATE START RECORDING
A32: ARU ID
A33: Garden width and length (m) | B33: 26.9*3.5
C35: Cover %
A36: Grass strata | B36: TRUE | C36: 5
A37: Herbaceous strata | B37: TRUE | C37: 60
A38: Shrub strata | B38: TRUE | C38: 15
A39: Tree strata | B39: TRUE | C39: 10
A40: Notes
A42: Shrub species | B42: Family | C42: Shrub cover % | D42: Native or non-native | E42: Notes | F42: Plant species | G42: Family | H42: Plant cover % | I42: Native or non-native
A43: Actinidia chinensis | B43: Actinidiaceae | C43: 5 | D43: non-native | F43: Aloe vera | H43: 1 | I43: non-native
A44: Rosa chinensis | B44: Rosaceae | C44: 1 | D44: non-native | F44: Ditch lily | H44: 1 | I44: non-native
A45: Wisteria sinensis | B45: Fabaceae | C45: 1 | D45: non-native | F45: Chives | H45: 35 | I45: non-native
F46: Sorrel | H46: 5 | I46: non-native
F47: Pussy willow | H47: 1 | I47: non-native
F48: Tiger lily | H48: 1 | I48: non-native
F49: Peony | H49: 1 | I49: Native
F50: Sweet woodruff | H50: 1 | I50: non-native
F51: New england aster | H51: 1 | I51: Native
...

Sheet Tree_per_garden
A1: ID | B1: Common name | C1: Native or non-native | D1: Species | E1: Family | F1: Coniferous_not | G1: DBH OUT (cm) | H1: Ht (m) | I1: CanopyDensity(%) | J1: CBH | K1: Density_g_cm3 | L1: biomassChave_kg | M1: Basal_area(m^2) | N1: CanopyWidth (m) | O1: CanopyLength(m) | P1: CrownArea(m2) | S1: Chave et al. 2014
A2: P11 | B2: Common fig | C2: Non-native | D2: Ficus carica | E2: Moraceae | F2: dec | G2: 13 | H2: 4 | I2: 15 | J2: 1.6 | K2: =IFERROR(VLOOKUP(TRIM(D2), Trees_density!$A:$B, 2, FALSE), "") -> 0.56 | L2: =IFERROR(0.0673 * ((K2 * G2^2 * H2)^0.976), "") -> 22.09401 | M2: =IFERROR(PI() * (G2/200)^2, "") -> 0.013273229 | N2: 1.7 | O2: 1.4 | P2: =IFERROR((PI() * N2 * O2) / 4, "") -> 1.8692476 | R2: Chojnacky 2013 | S2: https://academic.oup.com/forestry/article-abstract/87/1/129/602137?redirectedFrom=fulltext
A3: P11 | B3: Apple | C3: Non-native | D3: Malus domestica | E3: Rosaceae | F3: dec | G3: 42 | H3: 1.8 | I3: 5 | J3: 0.5 | K3: =IFERROR(VLOOKUP(TRIM(D3), Trees_density!$A:$B, 2, FALSE), "") -> 0.65 | L3: =IFERROR(0.0673 * ((K3 * G3^2 * H3)^0.976), "") -> 115.65038 | M3: =IFERROR(PI() * (G3/200)^2, "") -> 0.13854424 | N3: 2.6 | O3: 3.9 | P3: =IFERROR((PI() * N3 * O3) / 4, "") -> 7.9639374
A4: P12 | B4: Apple | C4: Non-native | D4: Malus domestica | E4: Rosaceae | F4: dec | G4: 5.3 | H4: 2.3 | I4: 60 | J4: 0.4 | K4: =IFERROR(VLOOKUP(TRIM(D4), Trees_density!$A:$B, 2, FALSE), "") -> 0.65 | L4: =IFERROR(0.0673 * ((K4 * G4^2 * H4)^0.976), "") -> 2.5837552 | M4: =IFERROR(PI() * (G4/200)^2, "") -> 0.0022061834 | N4: 2.2 | O4: 1.8 | P4: =IFERROR((PI() * N4 * O4) / 4, "") -> 3.1101767
A5: P12 | B5: Japanese persimmon | C5: Non-native | D5: Diospyros kaki | E5: Ebenaceae | F5: dec | G5: 6 | H5: 2.5 | I5: 30 | J5: 1.3 | K5: =IFERROR(VLOOKUP(TRIM(D5), Trees_density!$A:$B, 2, FALSE), "") -> 0.78 | L5: =IFERROR(0.0673 * ((K5 * G5^2 * H5)^0.976), "") -> 4.2661889 | M5: =IFERROR(PI() * (G5/200)^2, "") -> 0.0028274334 | N5: 2.1 | O5: 1.9 | P5: =IFERROR((PI() * N5 * O5) / 4, "") -> 3.1337387 | S5: Chave et al formula used:
A6: P12 | B6: Grape vine | C6: Non-native | D6: Vitis vinifera | E6: Vitaceae | F6: dec | G6: 5.1 | H6: 2 | I6: 25 | J6: 0.6 | K6: =IFERROR(VLOOKUP(TRIM(D6), Trees_density!$A:$B, 2, FALSE), "") -> 0.64 | L6: =IFERROR(0.0673 * ((K6 * G6^2 * H6)^0.976), "") -> 2.0598186 | M6: =IFERROR(PI() * (G6/200)^2, "") -> 0.0020428206 | N6: 5.5 | O6: 0.5 | P6: =IFERROR((PI() * N6 * O6) / 4, "") -> 2.1598449 | S6: DBH in c
A7: P12 | B7: Common pear | C7: Non-native | D7: Pyrus communis | E7: Rosaceae | F7: dec | G7: 10.2 | H7: 4.9 | I7: 85 | J7: 1.7 | K7: =IFERROR(VLOOKUP(TRIM(D7), Trees_density!$A:$B, 2, FALSE), "") -> 0.67 | L7: =IFERROR(0.0673 * ((K7 * G7^2 * H7)^0.976), "") -> 19.984026 | M7: =IFERROR(PI() * (G7/200)^2, "") -> 0.0081712825 | N7: 4.8 | O7: 3.8 | P7: =IFERROR((PI() * N7 * O7) / 4, "") -> 14.325663 | S7: Height in m
A8: P13 | B8: European plum | C8: Non-native | D8: Prunus domestica | E8: Rosaceae | F8: dec | G8: 33.3 | H8: 7 | I8: 40 | J8: 1.75 | K8: =IFERROR(VLOOKUP(TRIM(D8), Trees_density!$A:$B, 2, FALSE), "") -> 0.6 | L8: =IFERROR(0.0673 * ((K8 * G8^2 * H8)^0.976), "") -> 255.92783 | M8: =IFERROR(PI() * (G8/200)^2, "") -> 0.087092017 | N8: 6 | O8: 5.5 | P8: =IFERROR((PI() * N8 * O8) / 4, "") -> 25.918139 | S8: density in gcm-3
A9: P21 | B9: Common fig | C9: Non-native | D9: Ficus carica | E9: Moraceae | F9: dec | G9: 11.4 | H9: 4.4 | I9: 30 | J9: 1.5 | K9: =IFERROR(VLOOKUP(TRIM(D9), Trees_density!$A:$B, 2, FALSE), "") -> 0.56 | L9: =IFERROR(0.0673 * ((K9 * G9^2 * H9)^0.976), "") -> 18.764399 | M9: =IFERROR(PI() * (G9/200)^2, "") -> 0.010207035 | N9: 3.45 | O9: 3.1 | P9: =IFERROR((PI() * N9 * O9) / 4, "") -> 8.3998334 | S9: biomass in kg
A10: P21 | B10: Common fig | C10: Non-native | D10: Ficus carica | E10: Moraceae | F10: dec | G10: 10.9 | H10: 4.4 | I10: 30 | J10: 1.8 | K10: =IFERROR(VLOOKUP(TRIM(D10), Trees_density!$A:$B, 2, FALSE), "") -> 0.56 | L10: =IFERROR(0.0673 * ((K10 * G10^2 * H10)^0.976), "") -> 17.191466 | M10: =IFERROR(PI() * (G10/200)^2, "") -> 0.0093313156 | N10: 3.45 | O10: 3.1 | P10: =IFERROR((PI() * N10 * O10) / 4, "") -> 8.3998334
A11: P21 | B11: Ginkgo | C11: Non-native | D11: Ginkgo biloba | E11: Ginkgoaceae | F11: con | G11: 9 | H11: 3 | I11: 5 | J11: 2 | K11: =IFERROR(VLOOKUP(TRIM(D11), Trees_density!$A:$B, 2, FALSE), "") -> 0.44 | L11: =IFERROR(0.0673 * ((K11 * G11^2 * H11)^0.976), "") -> 6.4324527 | M11: =IFERROR(PI() * (G11/200)^2, "") -> 0.0063617251 | N11: 1 | O11: 0.9 | P11: =IFERROR((PI() * N11 * O11) / 4, "") -> 0.70685835
A12: P22 | B12: Western redcedar | C12: Native | D12: Thuja plicata | E12: Cupressaceae | F12: con | G12: 66.3 | H12: 23 | I12: 80 | J12: 0.5 | K12: =IFERROR(VLOOKUP(TRIM(D12), Trees_density!$A:$B, 2, FALSE), "") -> 0.32 | L12: =IFERROR(0.0673 * ((K12 * G12^2 * H12)^0.976), "") -> 1697.0015 | M12: =IFERROR(PI() * (G12/200)^2, "") -> 0.34523669 | N12: 7.4 | O12: 7.4 | P12: =IFERROR((PI() * N12 * O12) / 4, "") -> 43.008403
A13: P22 | B13: Western redcedar | C13: Native | D13: Thuja plicata | E13: Cupressaceae | F13: con | G13: 47.8 | H13: 19.6 | I13: 90 | J13: 0.4 | K13: =IFERROR(VLOOKUP(TRIM(D13), Trees_density!$A:$B, 2, FALSE), "") -> 0.32 | L13: =IFERROR(0.0673 * ((K13 * G13^2 * H13)^0.976), "") -> 766.52553 | M13: =IFERROR(PI() * (G13/200)^2, "") -> 0.17945091 | N13: 7.4 | O13: 7.5 | P13: =IFERROR((PI() * N13 * O13) / 4, "") -> 43.589598 | S13: crown projection area formula | V13: https://link.springer.com/content/pdf/10.1007/978-3-540-88307-4.pdf
A14: P22 | B14: Western redcedar | C14: Native | D14: Thuja plicata | E14: Cupressaceae | F14: con | G14: 49.4 | H14: 21.3 | I14: 90 | J14: 0.5 | K14: =IFERROR(VLOOKUP(TRIM(D14), Trees_density!$A:$B, 2, FALSE), "") -> 0.32 | L14: =IFERROR(0.0673 * ((K14 * G14^2 * H14)^0.976), "") -> 886.53307 | M14: =IFERROR(PI() * (G14/200)^2, "") -> 0.19166543 | N14: 7.4 | O14: 7.6 | P14: =IFERROR((PI() * N14 * O14) / 4, "") -> 44.170793 | S14: Forest Dynamics, Growth and Yield
A15: P22 | B15: Western redcedar | C15: Native | D15: Thuja plicata | E15: Cupressaceae | F15: con | G15: 59.6 | H15: 21.3 | I15: 90 | J15: 0.35 | K15: =IFERROR(VLOOKUP(TRIM(D15), Trees_density!$A:$B, 2, FALSE), "") -> 0.32 | L15: =IFERROR(0.0673 * ((K15 * G15^2 * H15)^0.976), "") -> 1278.853 | M15: =IFERROR(PI() * (G15/200)^2, "") -> 0.27898599 | N15: 7.4 | O15: 7.7 | P15: =IFERROR((PI() * N15 * O15) / 4, "") -> 44.751987 | S15: Hans Pretzsch 2009
A16: P22 | B16: Western redcedar | C16: Native | D16: Thuja plicata | E16: Cupressaceae | F16: con | G16: 48.6 | H16: 21.3 | I16: 90 | J16: 0.4 | K16: =IFERROR(VLOOKUP(TRIM(D16), Trees_density!$A:$B, 2, FALSE), "") -> 0.32 | L16: =IFERROR(0.0673 * ((K16 * G16^2 * H16)^0.976), "") -> 858.72466 | M16: =IFERROR(PI() * (G16/200)^2, "") -> 0.1855079 | N16: 7.4 | O16: 7.8 | P16: =IFERROR((PI() * N16 * O16) / 4, "") -> 45.333182 | S16: Area= pi x (width/2) x (length/2)
A17: P22 | B17: Western redcedar | C17: Native | D17: Thuja plicata | E17: Cupressaceae | F17: con | G17: 57.8 | H17: 21.3 | I17: 90 | J17: 0.6 | K17: =IFERROR(VLOOKUP(TRIM(D17), Trees_density!$A:$B, 2, FALSE), "") -> 0.32 | L17: =IFERROR(0.0673 * ((K17 * G17^2 * H17)^0.976), "") -> 1204.5451 | M17: =IFERROR(PI() * (G17/200)^2, "") -> 0.26238896 | N17: 7.4 | O17: 7.9 | P17: =IFERROR((PI() * N17 * O17) / 4, "") -> 45.914377
A18: P22 | B18: Western redcedar | C18: Native | D18: Thuja plicata | E18: Cupressaceae | F18: con | G18: 45 | H18: 21.3 | I18: 90 | J18: 0.55 | K18: =IFERROR(VLOOKUP(TRIM(D18), Trees_density!$A:$B, 2, FALSE), "") -> 0.32 | L18: =IFERROR(0.0673 * ((K18 * G18^2 * H18)^0.976), "") -> 738.9427 | M18: =IFERROR(PI() * (G18/200)^2, "") -> 0.15904313 | N18: 7.4 | O18: 7.1 | P18: =IFERROR((PI() * N18 * O18) / 4, "") -> 41.26482 | S18: Husch, B., Beers, T. W., & Kershaw, J. A. 2003. Forest Mensuration. Wiley.
A19: P22 | B19: Western redcedar | C19: Native | D19: Thuja plicata | E19: Cupressaceae | F19: con | G19: 58.6 | H19: 21.3 | I19: 90 | J19: 0.5 | K19: =IFERROR(VLOOKUP(TRIM(D19), Trees_density!$A:$B, 2, FALSE), "") -> 0.32 | L19: =IFERROR(0.0673 * ((K19 * G19^2 * H19)^0.976), "") -> 1237.303 | M19: =IFERROR(PI() * (G19/200)^2, "") -> 0.26970259 | N19: 7.4 | O19: 7.11 | P19: =IFERROR((PI() * N19 * O19) / 4, "") -> 41.322939 | S19: Basal Area = pi x (DBH/2)^2
A20: P32 | B20: Apple | C20: Non-native | D20: Malus domestica | E20: Rosaceae | F20: dec | G20: 17 | H20: 4 | I20: 30 | J20: 1.5 | K20: =IFERROR(VLOOKUP(TRIM(D20), Trees_density!$A:$B, 2, FALSE), "") -> 0.65 | L20: =IFERROR(0.0673 * ((K20 * G20^2 * H20)^0.976), "") -> 43.13853 | M20: =IFERROR(PI() * (G20/200)^2, "") -> 0.022698007 | N20: 3.4 | O20: 3.5 | P20: =IFERROR((PI() * N20 * O20) / 4, "") -> 9.3462381
A21: P32 | B21: Japanese maple | C21: Non-native | D21: Acer palmatum | E21: Aceraceae | F21: dec | G21: 31.46 | H21: 6.2 | I21: 10 | J21: 1.75 | K21: =IFERROR(VLOOKUP(TRIM(D21), Trees_density!$A:$B, 2, FALSE), "") -> 0.53 | L21: =IFERROR(0.0673 * ((K21 * G21^2 * H21)^0.976), "") -> 180.26343 | M21: =IFERROR(PI() * (G21/200)^2, "") -> 0.077733338 | N21: 5 | O21: 6 | P21: =IFERROR((PI() * N21 * O21) / 4, "") -> 23.561945
A22: M11 | B22: Paperbark maple | C22: Native | D22: Acer griseum | E22: Aceraceae | F22: dec | G22: 10.5 | H22: 6 | I22: 70 | J22: 2 | K22: =IFERROR(VLOOKUP(TRIM(D22), Trees_density!$A:$B, 2, FALSE), "") -> 0.62 | L22: =IFERROR(0.0673 * ((K22 * G22^2 * H22)^0.976), "") -> 23.890569 | M22: =IFERROR(PI() * (G22/200)^2, "") -> 0.0086590148 | N22: 2.4 | O22: 3.5 | P22: =IFERROR((PI() * N22 * O22) / 4, "") -> 6.5973446
A23: M11 | B23: Saucer Magnolia | C23: Non-native | D23: Magnolia × soulangeana | E23: Magnoliaceae | F23: dec | G23: 11.7 | H23: 4.5 | I23: 70 | J23: 2 | K23: =IFERROR(VLOOKUP(TRIM(D23), Trees_density!$A:$B, 2, FALSE), "") -> 0.45 | L23: =IFERROR(0.0673 * ((K23 * G23^2 * H23)^0.976), "") -> 16.299891 | M23: =IFERROR(PI() * (G23/200)^2, "") -> 0.010751315 | N23: 3.8 | O23: 2.5 | P23: =IFERROR((PI() * N23 * O23) / 4, "") -> 7.4612826
A24: M11 | B24: Silver birch | C24: Non-native | D24: Betula pendula | E24: Betulaceae | F24: dec | G24: 29.5 | H24: 14 | I24: 75 | J24: 3 | K24: =IFERROR(VLOOKUP(TRIM(D24), Trees_density!$A:$B, 2, FALSE), "") -> 0.57 | L24: =IFERROR(0.0673 * ((K24 * G24^2 * H24)^0.976), "") -> 377.97447 | M24: =IFERROR(PI() * (G24/200)^2, "") -> 0.068349275 | N24: 7 | O24: 5.5 | P24: =IFERROR((PI() * N24 * O24) / 4, "") -> 30.237829
A25: M11 | B25: Kousa dogwood | C25: Non-native | D25: Cornus kousa | E25: Cornaceae | F25: dec | G25: 19.14 | H25: 5 | I25: 40 | J25: 2 | K25: =IFERROR(VLOOKUP(TRIM(D25), Trees_density!$A:$B, 2, FALSE), "") -> 0.6 | L25: =IFERROR(0.0673 * ((K25 * G25^2 * H25)^0.976), "") -> 62.522461 | M25: =IFERROR(PI() * (G25/200)^2, "") -> 0.028772245 | N25: 5.7 | O25: 4 | P25: =IFERROR((PI() * N25 * O25) / 4, "") -> 17.907078
A26: M12 | B26: European beech | C26: Non-native | D26: Fagus sylvatica | E26: Fagaceae | F26: dec | G26: 43.01 | H26: 11 | I26: 80 | J26: 1.2 | K26: =IFERROR(VLOOKUP(TRIM(D26), Trees_density!$A:$B, 2, FALSE), "") -> 0.72 | L26: =IFERROR(0.0673 * ((K26 * G26^2 * H26)^0.976), "") -> 783.24637 | M26: =IFERROR(PI() * (G26/200)^2, "") -> 0.14528767 | N26: 4 | O26: 5 | P26: =IFERROR((PI() * N26 * O26) / 4, "") -> 15.707963
A27: M12 | B27: Sawara cypress | C27: Non-native | D27: Chamaecyparis pisifera | E27: Cupressaceae | F27: con | G27: 30 | H27: 11.2 | I27: 40 | J27: 1.2 | K27: =IFERROR(VLOOKUP(TRIM(D27), Trees_density!$A:$B, 2, FALSE), "") -> 0.39 | L27: =IFERROR(0.0673 * ((K27 * G27^2 * H27)^0.976), "") -> 216.90602 | M27: =IFERROR(PI() * (G27/200)^2, "") -> 0.070685835 | N27: 3.5 | O27: 3.5 | P27: =IFERROR((PI() * N27 * O27) / 4, "") -> 9.6211275
A28: M12 | B28: Sawara cypress | C28: Non-native | D28: Chamaecyparis pisifera | E28: Cupressaceae | F28: con | G28: 45 | H28: 14.6 | I28: 45 | J28: 1.2 | K28: =IFERROR(VLOOKUP(TRIM(D28), Trees_density!$A:$B, 2, FALSE), "") -> 0.39 | L28: =IFERROR(0.0673 * ((K28 * G28^2 * H28)^0.976), "") -> 619.9738 | M28: =IFERROR(PI() * (G28/200)^2, "") -> 0.15904313 | N28: 4.5 | O28: 4.5 | P28: =IFERROR((PI() * N28 * O28) / 4, "") -> 15.904313
A29: M12 | B29: Japanese maple | C29: Non-native | D29: Acer palmatum | E29: Aceraceae | F29: dec | G29: 14.14 | H29: 3.6 | I29: 40 | J29: 1.5 | K29: =IFERROR(VLOOKUP(TRIM(D29), Trees_density!$A:$B, 2, FALSE), "") -> 0.53 | L29: =IFERROR(0.0673 * ((K29 * G29^2 * H29)^0.976), "") -> 22.260597 | M29: =IFERROR(PI() * (G29/200)^2, "") -> 0.015703219 | N29: 1.8 | O29: 2 | P29: =IFERROR((PI() * N29 * O29) / 4, "") -> 2.8274334
A30: M12 | B30: Southern magnolia | C30: Non-native | D30: Magnolia grandifolia | E30: Magnoliaceae | F30: dec | G30: 15 | H30: 3.6 | I30: 75 | J30: 1.3 | K30: =IFERROR(VLOOKUP(TRIM(D30), Trees_density!$A:$B, 2, FALSE), "") -> 0.47 | L30: =IFERROR(0.0673 * ((K30 * G30^2 * H30)^0.976), "") -> 22.215902 | M30: =IFERROR(PI() * (G30/200)^2, "") -> 0.017671459 | N30: 3 | O30: 3 | P30: =IFERROR((PI() * N30 * O30) / 4, "") -> 7.0685835
A31: M14 | B31: Flowering dogwood | C31: Native | D31: Cornus florida | E31: Cornaceae | F31: dec | G31: 15 | H31: 8 | I31: 70 | J31: 4 | K31: =IFERROR(VLOOKUP(TRIM(D31), Trees_density!$A:$B, 2, FALSE), "") -> 0.63 | L31: =IFERROR(0.0673 * ((K31 * G31^2 * H31)^0.976), "") -> 64.464023 | M31: =IFERROR(PI() * (G31/200)^2, "") -> 0.017671459 | N31: 4.8 | O31: 3.5 | P31: =IFERROR((PI() * N31 * O31) / 4, "") -> 13.194689
... A75: R21 | B75: Japanese cherry | C75: Non-native | D75: Prunus serrulata | E75: Rosaceae | F75: dec | G75: 60 | H75: 8.2 | I75: 70 | J75: 1.2 | K75: =IFERROR(VLOOKUP(TRIM(D75), Trees_density!$A:$B, 2, FALSE), "") -> 0.56 | L75: =IFERROR(0.0673 * ((K75 * G75^2 * H75)^0.976), "") -> 881.21147 | M75: =IFERROR(PI() * (G75/200)^2, "") -> 0.28274334 | N75: 9.7 | O75: 8 | P75: =IFERROR((PI() * N75 * O75) / 4, "") -> 60.946897
A76: R21 | B76: Japanese cherry | C76: Non-native | D76: Prunus serrulata | E76: Rosaceae | F76: dec | G76: 52 | H76: 8.8 | I76: 60 | J76: 2,5 | K76: =IFERROR(VLOOKUP(TRIM(D76), Trees_density!$A:$B, 2, FALSE), "") -> 0.56 | L76: =IFERROR(0.0673 * ((K76 * G76^2 * H76)^0.976), "") -> 714.00326 | M76: =IFERROR(PI() * (G76/200)^2, "") -> 0.21237166 | N76: 9 | O76: 6.5 | P76: =IFERROR((PI() * N76 * O76) / 4, "") -> 45.945793
A77: R21 | B77: Common lilac | C77: Non-native | D77: Syringa vulgaris | E77: Oleaceae | F77: dec | G77: 10 | H77: 5 | I77: 30 | J77: 1.66 | K77: =IFERROR(VLOOKUP(TRIM(D77), Trees_density!$A:$B, 2, FALSE), "") -> 0.55 | L77: =IFERROR(0.0673 * ((K77 * G77^2 * H77)^0.976), "") -> 16.173491 | M77: =IFERROR(PI() * (G77/200)^2, "") -> 0.0078539816 | N77: 3 | O77: 2.5 | P77: =IFERROR((PI() * N77 * O77) / 4, "") -> 5.8904862
A78: R21 | B78: Common lilac | C78: Non-native | D78: Syringa vulgaris | E78: Oleaceae | F78: dec | G78: 18.03 | H78: 5.5 | I78: 50 | J78: 1.2 | K78: =IFERROR(VLOOKUP(TRIM(D78), Trees_density!$A:$B, 2, FALSE), "") -> 0.55 | L78: =IFERROR(0.0673 * ((K78 * G78^2 * H78)^0.976), "") -> 56.092745 | M78: =IFERROR(PI() * (G78/200)^2, "") -> 0.025531794 | N78: 4.3 | O78: 6.5 | P78: =IFERROR((PI() * N78 * O78) / 4, "") -> 21.951879
A79: R21 | B79: Southern magnolia | C79: Non-native | D79: Magnolia grandifolia | E79: Magnoliaceae | F79: dec | G79: 37 | H79: 6 | I79: 60 | J79: 2.5 | K79: =IFERROR(VLOOKUP(TRIM(D79), Trees_density!$A:$B, 2, FALSE), "") -> 0.47 | L79: =IFERROR(0.0673 * ((K79 * G79^2 * H79)^0.976), "") -> 213.10221 | M79: =IFERROR(PI() * (G79/200)^2, "") -> 0.10752101 | N79: 4.3 | O79: 4 | P79: =IFERROR((PI() * N79 * O79) / 4, "") -> 13.508848
A80: R22 | B80: Rosebay rhododendron | C80: Non-native | D80: Rhododendron maximum | E80: Ericaceae | F80: dec | G80: 17.12 | H80: 4.5 | I80: 70 | J80: 1.7 | K80: =IFERROR(VLOOKUP(TRIM(D80), Trees_density!$A:$B, 2, FALSE), "") -> 0.47 | L80: =IFERROR(0.0673 * ((K80 * G80^2 * H80)^0.976), "") -> 35.753398 | M80: =IFERROR(PI() * (G80/200)^2, "") -> 0.02301958 | N80: 2.2 | O80: 4.8 | P80: =IFERROR((PI() * N80 * O80) / 4, "") -> 8.2938046
A81: R22 | B81: Rosebay rhododendron | C81: Non-native | D81: Rhododendron maximum | E81: Ericaceae | F81: dec | G81: 16.25 | H81: 4.5 | I81: 65 | J81: 1.5 | K81: =IFERROR(VLOOKUP(TRIM(D81), Trees_density!$A:$B, 2, FALSE), "") -> 0.47 | L81: =IFERROR(0.0673 * ((K81 * G81^2 * H81)^0.976), "") -> 32.292655 | M81: =IFERROR(PI() * (G81/200)^2, "") -> 0.02073942 | N81: 2.7 | O81: 4.8 | P81: =IFERROR((PI() * N81 * O81) / 4, "") -> 10.17876
A82: R22 | B82: Cherry laurel | C82: Non-native | D82: Prunus laurocerasus | E82: Rosaceae | F82: dec | G82: 39.7 | H82: 12 | I82: 70 | J82: 1.5 | K82: =IFERROR(VLOOKUP(TRIM(D82), Trees_density!$A:$B, 2, FALSE), "") -> 0.48 | L82: =IFERROR(0.0673 * ((K82 * G82^2 * H82)^0.976), "") -> 490.93781 | M82: =IFERROR(PI() * (G82/200)^2, "") -> 0.12378582 | N82: 7.5 | O82: 6 | P82: =IFERROR((PI() * N82 * O82) / 4, "") -> 35.342917
A83: R22 | B83: Taiwanese photinia | C83: Non-native | D83: Photinia serratifolia | E83: Rosaceae | F83: dec | G83: 9.43 | H83: 3.5 | I83: 70 | J83: 1 | K83: =IFERROR(VLOOKUP(TRIM(D83), Trees_density!$A:$B, 2, FALSE), "") -> 0.58 | L83: =IFERROR(0.0673 * ((K83 * G83^2 * H83)^0.976), "") -> 10.724524 | M83: =IFERROR(PI() * (G83/200)^2, "") -> 0.0069841453 | N83: 2 | O83: 2.5 | P83: =IFERROR((PI() * N83 * O83) / 4, "") -> 3.9269908
...

Sheet Native_vs_not_GRAPHING
A1: House | B1: Overall_garden_diversity | C1: Garden_size | D1: Number_tree_species_total | E1: Native_number_trees | F1: Native_number_plantsnshrubs | G1: Native_percent_total | H1: Economic_level | J1: index,House,shannon_garden
A2: M11 | B2: 83 | C2: 57 | D2: 4 | E2: 1 | F2: 17 | G2: =B2/(E2+F2) -> 4.6111111 | H2: 78.5 | J2: 0,M11,4.4188406077966
A3: M12 | B3: 14 | C3: 75.19 | D3: 5 | E3: 0 | F3: 5 | G3: =B3/(E3+F3) -> 2.8 | H3: 78.5 | J3: 1,M12,2.54003630382098
A4: M13 | B4: 5 | C4: 12.3 | D4: 0 | E4: 0 | F4: 0 | G4: 0 | H4: 78.5 | J4: 2,M13,1.6094379124341005
A5: M14 | B5: 55 | C5: 160 | D5: 3 | E5: 2 | F5: 8 | G5: =B5/(E5+F5) -> 5.5 | H5: 78.5 | J5: 3,M14,4.007333185232471
A6: M21 | B6: 10 | C6: 142.5 | D6: 0 | E6: 0 | F6: 4 | G6: =B6/(E6+F6) -> 2.5 | H6: 104 | J6: 4,M21,2.3025850929940455
A7: M22 | B7: 14 | C7: 110 | D7: 1 | E7: 0 | F7: 1 | G7: =B7/(E7+F7) -> 14 | H7: 104 | J7: 5,M22,2.639057329615258
A8: M23 | B8: 41 | C8: 81 | D8: 3 | E8: 1 | F8: 8 | G8: =B8/(E8+F8) -> 4.5555556 | H8: 104 | J8: 6,M23,3.713572066704308
A9: M24 | B9: 15 | C9: 198 | D9: 3 | E9: 1 | F9: 4 | G9: =B9/(E9+F9) -> 3 | H9: 104 | J9: 7,M24,2.615630577027551
A10: M31 | B10: 27 | C10: 173.25 | D10: 7 | E10: 1 | F10: 3 | G10: =B10/(E10+F10) -> 6.75 | H10: 98 | J10: 8,M31,3.2444926304072963
A11: M41 | B11: 35 | C11: 142 | D11: 3 | E11: 1 | F11: 4 | G11: =B11/(E11+F11) -> 7 | H11: 93 | J11: 9,M41,3.5553480614894135
A12: M42 | B12: 33 | C12: 209 | D12: 5 | E12: 1 | F12: 4 | G12: =B12/(E12+F12) -> 6.6 | H12: 93 | J12: 10,M42,3.328471881330735
A13: P11 | B13: 10 | C13: 55.85 | D13: 2 | E13: 0 | F13: 1 | G13: =B13/(E13+F13) -> 10 | H13: 52 | J13: 11,P11,2.3025850929940455
A14: P12 | B14: 18 | C14: 62.5 | D14: 4 | E14: 0 | F14: 2 | G14: =B14/(E14+F14) -> 9 | H14: 52 | J14: 12,P12,2.890371757896165
A15: P13 | B15: 30 | C15: 187 | D15: 1 | E15: 0 | F15: 2 | G15: =B15/(E15+F15) -> 15 | H15: 52 | J15: 13,P13,3.367295829986473
A16: P14 | B16: 13 | C16: 50 | D16: 0 | E16: 0 | F16: 1 | G16: =B16/(E16+F16) -> 13 | H16: 52 | J16: 14,P14,2.564949357461537
... A31: R34 | B31: 28 | C31: 132 | D31: 4 | E31: 1 | F31: 3 | G31: =B31/(E31+F31) -> 7 | H31: 135 | J31: 29,R34,3.3322045101752034

Sheet Plantsnshrub_per_garden
A1: House | B1: Plants | C1: Native_or_not | D1: Shrubs | E1: Native_or_non
A2: P11 | B2: Rutabaga | C2: =IFERROR(VLOOKUP(B2,Shrub_plantNative_Nonnative!A:B,2,FALSE),"Verificar") -> non | D2: Juniperus comunis | E2: native
B3: Leek | C3: =IFERROR(VLOOKUP(B3,Shrub_plantNative_Nonnative!A:B,2,FALSE),"Verificar") -> non | D3: Ilex | E3: non
B4: Bok choy | C4: =IFERROR(VLOOKUP(B4,Shrub_plantNative_Nonnative!A:B,2,FALSE),"Verificar") -> non | D4: Chamaecyparis | E4: =IFERROR(VLOOKUP(D4,Shrub_plantNative_Nonnative!A:B,2,FALSE),"Verificar") -> non
B5: Garlic | C5: =IFERROR(VLOOKUP(B5,Shrub_plantNative_Nonnative!A:B,2,FALSE),"Verificar") -> non
B6: English Holly | C6: =IFERROR(VLOOKUP(B6,Shrub_plantNative_Nonnative!A:B,2,FALSE),"Verificar") -> non
A7: P12 | B7: Aloe vera | C7: =IFERROR(VLOOKUP(B7,Shrub_plantNative_Nonnative!A:B,2,FALSE),"Verificar") -> non | D7: Actinidia chinensis | E7: =IFERROR(VLOOKUP(D7,Shrub_plantNative_Nonnative!A:B,2,FALSE),"Verificar") -> non
B8: Ditch lily | C8: =IFERROR(VLOOKUP(B8,Shrub_plantNative_Nonnative!A:B,2,FALSE),"Verificar") -> non | D8: Rosa chinensis | E8: non
B9: Chives | C9: =IFERROR(VLOOKUP(B9,Shrub_plantNative_Nonnative!A:B,2,FALSE),"Verificar") -> non | D9: Wisteria sinensis | E9: =IFERROR(VLOOKUP(D9,Shrub_plantNative_Nonnative!A:B,2,FALSE),"Verificar") -> non
B10: Sorrel | C10: =IFERROR(VLOOKUP(B10,Shrub_plantNative_Nonnative!A:B,2,FALSE),"Verificar") -> non
B11: Pussy willow | C11: =IFERROR(VLOOKUP(B11,Shrub_plantNative_Nonnative!A:B,2,FALSE),"Verificar") -> native
B12: Tiger lily | C12: =IFERROR(VLOOKUP(B12,Shrub_plantNative_Nonnative!A:B,2,FALSE),"Verificar") -> non
B13: Peony | C13: =IFERROR(VLOOKUP(B13,Shrub_plantNative_Nonnative!A:B,2,FALSE),"Verificar") -> non
B14: Sweet woodruff | C14: =IFERROR(VLOOKUP(B14,Shrub_plantNative_Nonnative!A:B,2,FALSE),"Verificar") -> non
B15: New england aster | C15: =IFERROR(VLOOKUP(B15,Shrub_plantNative_Nonnative!A:B,2,FALSE),"Verificar") -> native
B16: Large yellow loosestrife | C16: =IFERROR(VLOOKUP(B16,Shrub_plantNative_Nonnative!A:B,2,FALSE),"Verificar") -> non
B17: Indian Shot | C17: =IFERROR(VLOOKUP(B17,Shrub_plantNative_Nonnative!A:B,2,FALSE),"Verificar") -> non
A18: P13 | B18: mugwort | C18: =IFERROR(VLOOKUP(B18,Shrub_plantNative_Nonnative!A:B,2,FALSE),"Verificar") -> non | D18: china rose | E18: =IFERROR(VLOOKUP(D18,Shrub_plantNative_Nonnative!A:B,2,FALSE),"Verificar") -> non
B19: Jerusalem artichoke | C19: =IFERROR(VLOOKUP(B19,Shrub_plantNative_Nonnative!A:B,2,FALSE),"Verificar") -> non | D19: Chinese boxthorn | E19: =IFERROR(VLOOKUP(D19,Shrub_plantNative_Nonnative!A:B,2,FALSE),"Verificar") -> non
B20: sweet fennel | C20: =IFERROR(VLOOKUP(B20,Shrub_plantNative_Nonnative!A:B,2,FALSE),"Verificar") -> non | D20: Chinese wolfberry | E20: =IFERROR(VLOOKUP(D20,Shrub_plantNative_Nonnative!A:B,2,FALSE),"Verificar") -> non
B21: field mustard | C21: =IFERROR(VLOOKUP(B21,Shrub_plantNative_Nonnative!A:B,2,FALSE),"Verificar") -> non
B22: rue | C22: =IFERROR(VLOOKUP(B22,Shrub_plantNative_Nonnative!A:B,2,FALSE),"Verificar") -> non
B23: lady fern | C23: =IFERROR(VLOOKUP(B23,Shrub_plantNative_Nonnative!A:B,2,FALSE),"Verificar") -> native
B24: dandelion | C24: =IFERROR(VLOOKUP(B24,Shrub_plantNative_Nonnative!A:B,2,FALSE),"Verificar") -> non
B25: bouncing-bet | C25: non
B26: rhubarb | C26: =IFERROR(VLOOKUP(B26,Shrub_plantNative_Nonnative!A:B,2,FALSE),"Verificar") -> non
B27: Spanish bluebell | C27: =IFERROR(VLOOKUP(B27,Shrub_plantNative_Nonnative!A:B,2,FALSE),"Verificar") -> non
B28: garden snapdragon | C28: =IFERROR(VLOOKUP(B28,Shrub_plantNative_Nonnative!A:B,2,FALSE),"Verificar") -> non
B29: wall lettuce | C29: =IFERROR(VLOOKUP(B29,Shrub_plantNative_Nonnative!A:B,2,FALSE),"Verificar") -> non
B30: common evening-primrose | C30: non
B31: orpine | C31: =IFERROR(VLOOKUP(B31,Shrub_plantNative_Nonnative!A:B,2,FALSE),"Verificar") -> non
B32: clustered bellflower | C32: =IFERROR(VLOOKUP(B32,Shrub_plantNative_Nonnative!A:B,2,FALSE),"Verificar") -> non
B33: feverfew | C33: =IFERROR(VLOOKUP(B33,Shrub_plantNative_Nonnative!A:B,2,FALSE),"Verificar") -> non
B34: European plum | C34: =IFERROR(VLOOKUP(B34,Shrub_plantNative_Nonnative!A:B,2,FALSE),"Verificar") -> non
B35: fringed willowherb | C35: =IFERROR(VLOOKUP(B35,Shrub_plantNative_Nonnative!A:B,2,FALSE),"Verificar") -> native
B36: clammy ground cherry | C36: =IFERROR(VLOOKUP(B36,Shrub_plantNative_Nonnative!A:B,2,FALSE),"Verificar") -> non
B37: creeping woodsorrel | C37: =IFERROR(VLOOKUP(B37,Shrub_plantNative_Nonnative!A:B,2,FALSE),"Verificar") -> non
B38: spearmint | C38: =IFERROR(VLOOKUP(B38,Shrub_plantNative_Nonnative!A:B,2,FALSE),"Verificar") -> non
B39: obedient plant | C39: =IFERROR(VLOOKUP(B39,Shrub_plantNative_Nonnative!A:B,2,FALSE),"Verificar") -> non
B40: common plantain | C40: =IFERROR(VLOOKUP(B40,Shrub_plantNative_Nonnative!A:B,2,FALSE),"Verificar") -> non
...

Sheet Shrub_plantNative_Nonnative
A1: Plant_and_shrub_species | B1: Native_or_not
A2: African Marigold | B2: non
A3: Agueweed | B3: non
A4: Aleutian Maidenhair | B4: native
A5: Aloe Vera | B5: non
A6: American Alumroot | B6: non
A7: American Beautyberry | B7: non
A8: Anise | B8: non
A9: Annual Honesty | B9: non
A10: August Lily | B10: non
A11: Asian Virginsbower | B11: non
A12: Bacopa | B12: non
... A359: Wisteria Sinensis | B359: non

Sheet Unique_plant_species
A1: African Marigold
A2: Agueweed
A3: Aleutian Maidenhair
A4: Aloe Vera
A5: American Alumroot
A6: American Beautyberry
A7: Anise
A8: Annual Honesty
A9: August Lily
A10: Asian Virginsbower
A11: Bacopa
A12: Balloon Flower
... A255: Hakonechloa macra

Sheet Unique_shrub_species
A1: Actinidia Chinensis
A2: Alpen Rose
A3: Arborvitae
A4: Autumn Sage
A5: Bay Laurel
A6: Bigleaf Hydrangea
A7: Black Cherry
A8: Blue Blossom
A9: Blueblossom
A10: Border Forsythia
A11: Buttonwood
A12: Canada Yew
... A118: Yellow Flag

Sheet Unique_total_plant_shrubspecies
A1: African Marigold
A2: Agueweed
A3: Aleutian Maidenhair
A4: Aloe Vera
A5: American Alumroot
A6: American Beautyberry
A7: Anise
A8: Annual Honesty
A9: August Lily
A10: Asian Virginsbower
A11: Bacopa
A12: Balloon Flower
... A359: Wisteria Sinensis

Sheet total_all_species
A1: added unique plants, shrubs and trees
A2: Ficus carica
A3: Malus domestica
A4: Diospyros kaki
A5: Vitis vinifera
A6: Pyrus communis
A7: Prunus domestica
A8: Ginkgo biloba
A9: Thuja plicata
A10: Acer palmatum
A11: Acer griseum
A12: Magnolia × soulangeana
... A389: Wisteria Sinensis

Sheet Everything_statistics
A1: House | B1: Bird_Diversity | C1: Canopy_cover_radius_50m | D1: Canopy_cover_radius_100m | E1: Economic_level | F1: Plant_and_shrub_diversity | G1: Tree_species_diversity | H1: Overall_garden_diversity | I1: Garden_size | J1: Canopy_cover_garden | K1: Grass_percentage | L1: Herbaceous_percentage | M1: Shrub_percentage | N1: Tree_percentage | O1: Overall_family_diversity
A2: M11 | B2: 28 | C2: 20.408163 | D2: 20.072727 | E2: 78.5 | F2: 79 | G2: 4 | H2: 83 | I2: 57 | J2: 36.521015 | K2: 0 | L2: 60 | M2: 20 | N2: 20
A3: M12 | B3: 42 | C3: 13.702624 | D3: 30.589949 | E3: 78.5 | F3: 9 | G3: 5 | H3: 14 | I3: 75.19 | J3: 42.411501 | K3: 30 | L3: 3 | M3: 5 | N3: 15
A4: M13 | B4: 21 | C4: 42.857143 | D4: 37.928519 | E4: 78.5 | F4: 5 | G4: 0 | H4: 5 | I4: 12.3 | J4: 0 | K4: 0 | L4: 20 | M4: 30 | N4: 10
A5: M14 | B5: 48 | C5: 50.724638 | D5: 35.204082 | E5: 78.5 | F5: 52 | G5: 3 | H5: 55 | I5: 160 | J5: 30 | K5: 10 | L5: 30 | M5: 20 | N5: 10
A6: M21 | B6: 48 | C6: 24.561404 | D6: 21.2627 | E6: 104 | F6: 10 | G6: 0 | H6: 10 | I6: 142.5 | J6: 0 | K6: 75 | L6: 5 | M6: 5 | N6: 10
A7: M22 | B7: 42 | C7: 30.3207 | D7: 27.352298 | E7: 104 | F7: 13 | G7: 1 | H7: 14 | I7: 110 | J7: 14.137167 | K7: 75 | L7: 20 | M7: 5 | N7: 10
A8: M23 | B8: 42 | C8: 44.057971 | D8: 32.234432 | E8: 104 | F8: 38 | G8: 3 | H8: 41 | I8: 81 | J8: 43.825218 | K8: 40 | L8: 50 | M8: 10 | N8: 50
A9: M24 | B9: 48 | C9: 37.790698 | D9: 26.29279 | E9: 104 | F9: 12 | G9: 3 | H9: 15 | I9: 198 | J9: 51.36504 | K9: 40 | L9: 40 | M9: 15 | N9: 30
A10: M31 | B10: 46 | C10: 7.6246334 | D10: 5.8738216 | E10: 98 | F10: 20 | G10: 7 | H10: 27 | I10: 173.25 | J10: 38.170351 | K10: 40 | L10: 20 | M10: 20 | N10: 15
A11: M41 | B11: 20 | C11: 17.201166 | D11: 20.684632 | E11: 93 | F11: 32 | G11: 3 | H11: 35 | I11: 142 | J11: 30.630528 | K11: 0 | L11: 10 | M11: 70 | N11: 10
A12: M42 | B12: 48 | C12: 30.635838 | D12: 25.639153 | E12: 93 | F12: 28 | G12: 5 | H12: 33 | I12: 209 | J12: 54.192473 | K12: 50 | L12: 30 | M12: 10 | N12: 25
A13: P11 | B13: 40 | C13: 15.339233 | D13: 11.82016 | E13: 52 | F13: 8 | G13: 2 | H13: 10 | I13: 55.85 | J13: 12.487831 | K13: 40 | L13: 50 | M13: 10 | N13: 10
... A31: R34 | B31: 38 | C31: 66.374269 | D31: 59.477124 | E31: 135 | F31: 24 | G31: 4 | H31: 28 | I31: 132 | J31: 60.554198 | K31: 40 | L31: 20 | M31: 10 | N31: 20

Sheet Treesall_nativeness_con_dec
A1: tree_species | B1: Native_or_not | C1: Coniferous_decidous
A2: Ficus carica | B2: non
A3: Malus domestica | B3: non
A4: Diospyros kaki | B4: non
A5: Vitis vinifera | B5: non
A6: Pyrus communis | B6: non
A7: Prunus domestica | B7: non
A8: Ginkgo biloba | B8: non
A9: Thuja plicata | B9: native
A10: Acer palmatum | B10: non
A11: Acer griseum | B11: non
A12: Magnolia × soulangeana | B12: non
A13: Betula pendula | B13: non
... A48: Camellia japonica | B48: non

Sheet Van_trees_count
A3: Rótulos de Linha | B3: Contagem de SPECIES_NAME | D3: Índice de Shannon H' = 4.22834 | E3: High diversity value
A4: SERRULATA | B4: 13705
A5: PLATANOIDES | B5: 12760 | D5: Equabilidade de Pielou J = 0.67246 | E5: equitability moderate, distribution of abundance is not very uniform
A6: CERASIFERA | B6: 10984
A7: RUBRUM | B7: 9860 | D7: Simpson D = 0.0275289
A8: SYLVATICA | B8: 7735
A9: AMERICANA | B9: 5970 | D9: Simpson 1 − D = 0.97247
A10: BETULUS | B10: 5853
A11: PLICATA | B11: 5694 | D11: Simpson 1 / D (número efetivo) = 36.325 | E11: Low probability of picking two individuals of the same species, 36 species equally abundant
A12: FREEMANII X | B12: 4453
A13: EUCHLORA X | B13: 4125
A14: CAMPESTRE | B14: 3747
A15: SPECIES | B15: 3559
A16: PERSICA | B16: 2974
A17: KOBUS | B17: 2871
A18: JAPONICUM | B18: 2683
A19: X YEDOENSIS | B19: 2642
A20: MENZIESII | B20: 2617
A21: HIPPOCASTANUM | B21: 2554
A22: RUBRA | B22: 2494
A23: PALUSTRIS | B23: 2354
... A541: ARBUTIFOLIA | B541: 1
A542: (vazio)
A543: Total Geral | B543: 183849

Sheet Table_Garden_trees_count
A3: Rótulos de Linha | B3: Contagem de Trees
A4: Thuja plicata | B4: 14
A5: Cercidiphyllum japonicum | B5: 12
A6: Malus domestica | B6: 8
A7: Acer palmatum | B7: 7
A8: Ficus carica | B8: 6
A9: Cornus kousa | B9: 5
A10: Prunus serrulata | B10: 5
A11: Magnolia grandifolia | B11: 4
A12: Cedrus deodara | B12: 3
A13: Prunus domestica | B13: 3
A14: Chamaecyparis lawsoniana | B14: 3
A15: Syringa vulgaris | B15: 3
... A50: Magnolia × soulangeana | B50: 1
A51: (vazio)
A52: Total Geral | B52: 118

Sheet Table_plants_count
A1: Garden_plants | B1: Count | C1: proporção | D1: pᵢ * ln(pᵢ) | E1: pᵢ²
A2: pacific rhododendron | B2: 14 | C2: =B2 / SUM($B$2:$B$362) -> 0.019914651 | D2: =IF(C2=0,0, C2 * LN(C2)) -> -0.077991741 | E2: =C2^2 -> 0.00039659334
A3: spanish bluebell | B3: 13 | C3: =B3 / SUM($B$2:$B$362) -> 0.018492176 | D3: =IF(C3=0,0, C3 * LN(C3)) -> -0.07379132 | E3: =C3^2 -> 0.00034196059
A4: chives | B4: 12 | C4: =B4 / SUM($B$2:$B$362) -> 0.017069701 | D4: =IF(C4=0,0, C4 * LN(C4)) -> -0.06948137 | E4: =C4^2 -> 0.0002913747
A5: china rose | B5: 11 | C5: =B5 / SUM($B$2:$B$362) -> 0.015647226 | D5: =IF(C5=0,0, C5 * LN(C5)) -> -0.065052742 | E5: =C5^2 -> 0.00024483569
A6: creeping buttercup | B6: 11 | C6: =B6 / SUM($B$2:$B$362) -> 0.015647226 | D6: =IF(C6=0,0, C6 * LN(C6)) -> -0.065052742 | E6: =C6^2 -> 0.00024483569
A7: plantain lily | B7: 10 | C7: =B7 / SUM($B$2:$B$362) -> 0.014224751 | D7: =IF(C7=0,0, C7 * LN(C7)) -> -0.06049462 | E7: =C7^2 -> 0.00020234354
A8: peony | B8: 10 | C8: =B8 / SUM($B$2:$B$362) -> 0.014224751 | D8: =IF(C8=0,0, C8 * LN(C8)) -> -0.06049462 | E8: =C8^2 -> 0.00020234354
A9: common boxwood | B9: 9 | C9: =B9 / SUM($B$2:$B$362) -> 0.012802276 | D9: =IF(C9=0,0, C9 * LN(C9)) -> -0.055794013 | E9: =C9^2 -> 0.00016389827
A10: ditch lily | B10: 8 | C10: =B10 / SUM($B$2:$B$362) -> 0.011379801 | D10: =IF(C10=0,0, C10 * LN(C10)) -> -0.050935025 | E10: =C10^2 -> 0.00012949987
A11: bigleaf hydrangea | B11: 7 | C11: =B11 / SUM($B$2:$B$362) -> 0.0099573257 | D11: =IF(C11=0,0, C11 * LN(C11)) -> -0.045897763 | E11: =C11^2 -> 9.9148336e-05
A12: english ivy | B12: 7 | C12: =B12 / SUM($B$2:$B$362) -> 0.0099573257 | D12: =IF(C12=0,0, C12 * LN(C12)) -> -0.045897763 | E12: =C12^2 -> 9.9148336e-05
A13: japanese maple | B13: 7 | C13: =B13 / SUM($B$2:$B$362) -> 0.0099573257 | D13: =IF(C13=0,0, C13 * LN(C13)) -> -0.045897763 | E13: =C13^2 -> 9.9148336e-05
... A362: japanese laurel | B362: 1 | C362: =B362 / SUM($B$2:$B$362) -> 0.0014224751 | D362: =IF(C362=0,0, C362 * LN(C362)) -> -0.009324832 | E362: =C362^2 -> 2.0234354e-06
A363: (vazio)
A364: Total Geral | B364: 703 | D364: =-SUM(D2:D362) -> 5.5685889 | E364: =SUM(E2:E362) -> 0.0055381428
D365: Shannon value above | E365: SimpsonD above
E366: =1 - E364 -> 0.99446186
E367: 1 – D above
E368: =1 / E364 -> 180.56595
E369: 1/D above, Simpson Reciprocal Index

Sheet Shannon_garden_trees
A1: Species | B1: Count | C1: pi | D1: ln(pi) | E1: pi*ln(pi)
A2: Thuja plicata | B2: 14 | C2: 0.118644068 | D2: -2131176399 | E2: -0.25209403 | G2: • Shannon H': 3.436 | H2: Usually varies between 0 to 4,5 in extremely diverse communities. 3,4 means there is high structural diversity in the tree community.Species with abundance relatively well distributed, very heterogenous community.
A3: Cercidiphyllum japonicum | B3: 12 | C3: 0.101694915 | D3: -2285347743 | E3: -0.23237279 | G3: • Equabilidade J: 0.892 | H3: 0 means very unequal and 1 means completely uniform distribution. 0.89 means there are few dominating species that are not in enough numbers to create inequality. Well balanced distribution.
A4: Malus domestica | B4: 8 | C4: 0.06779661 | D4: -2691243082 | E4: -0.18240778
A5: Acer palmatum | B5: 7 | C5: 0.059322034 | D5: -2821378888 | E5: -0.16731753
A6: Ficus carica | B6: 6 | C6: 0.050847458 | D6: -2975529566 | E6: -0.15118359 | G6: Simpson Results:
A7: Cornus kousa | B7: 5 | C7: 0.042372881 | D7: -316464153 | E7: -0.13412127 | G7: D= 0,0474 | H7: 0,0474 is low, low dominance of any species. The closer to 0, the bigger the diversity.
A8: Prunus serrulata | B8: 5 | C8: 0.042372881 | D8: -316464153 | E8: -0.13412127 | G8: 1-D= 0,9526 | H8: 0,9526 is high meaning trees are well distributed and diverse.
A9: Magnolia grandifolia | B9: 4 | C9: 0.033898305 | D9: -3384390263 | E9: -0.11474296 | G9: 1/D=21,10 | H9: 21 species with equal abundance, useful as Shannon tends to overestimate diversity when there are rare species.
A10: Cedrus deodara | B10: 3 | C10: 0.025423729 | D10: -3674239085 | E10: -0.09340582
A11: Prunus domestica | B11: 3 | C11: 0.025423729 | D11: -3674239085 | E11: -0.09340582
A12: Chamaecyparis lawsoniana | B12: 3 | C12: 0.025423729 | D12: -3674239085 | E12: -0.09340582
A13: Syringa vulgaris | B13: 3 | C13: 0.025423729 | D13: -3674239085 | E13: -0.09340582
A14: Chamaecyparis pisifera | B14: 3 | C14: 0.025423729 | D14: -3674239085 | E14: -0.09340582
A15: Sorbus aucuparia | B15: 3 | C15: 0.025423729 | D15: -3674239085 | E15: -0.09340582
A16: Cornus florida | B16: 2 | C16: 0.016949153 | D16: -4075833024 | E16: -0.06903214
A17: Rhododendron maximum | B17: 2 | C17: 0.016949153 | D17: -4075833024 | E17: -0.06903214
A18: Rhododendron macrophyllum | B18: 2 | C18: 0.016949153 | D18: -4075833024 | E18: -0.06903214
A19: Picea sitchensis | B19: 2 | C19: 0.016949153 | D19: -4075833024 | E19: -0.06903214
A20: Prunus cerasifera | B20: 2 | C20: 0.016949153 | D20: -4075833024 | E20: -0.06903214
A21: Parrotia persica | B21: 2 | C21: 0.016949153 | D21: -4075833024 | E21: -0.06903214
... A48: Magnolia × soulangeana | B48: 1 | C48: 0.008474576 | D48: -4770684624 | E48: -0.04045115

Sheet (notusing)Trees_complete
A1: Species | B1: Family | C1: DBH INP (cm) | D1: DBH OUT (cm) | E1: Ht (m) | F1: CanopyDensity(%) | G1: CW (m) | H1: CA | I1: CBH | J1: Cavities (C)/ Dead wood (D) | K1: Fruit (F)/Nuts (N) | L1: flower | M1: Notes | S1: canpoy area= pi x (length/2) x (width/2)
A2: Ficus carica | B2: Moraceae | C2: 13 | D2: 13 | E2: 4 | F2: 15 | G2: 1.7*1.4 | H2: 3.2986723 | I2: 1.6 | K2: F | L2: FALSE
A3: Malus domestica | B3: Rosaceae | C3: 42 | D3: 42 | E3: 1.8 | F3: 5 | G3: 2.6*3.9 | H3: 9.1891585 | I3: 0.5 | J3: C, D | K3: - | L3: FALSE | M3: Trimmed heavily
A4: Malus domestica | B4: Rosaceae | C4: 5.3 | D4: 5.3 | E4: 2.3 | F4: 60 | G4: 2.2*1.8 | H4: 4.2411501 | I4: 0.4 | K4: - | L4: TRUE
A5: Diospyros kaki | B5: Ebenaceae | C5: 6 | D5: 6 | E5: 2.5 | F5: 30 | G5: 2.1*1.9 | H5: 4.4767695 | I5: 1.3 | K5: - | L5: FALSE
A6: Vitis vinifera | B6: Vitaceae | C6: 5.1 | D6: 5.1 | E6: 2 | F6: 25 | G6: 5.5*0.5 | H6: 1.1780972 | I6: 0.6 | K6: - | L6: TRUE | M6: vine
A7: Pyrus communis | B7: Rosaceae | C7: 10.2 | D7: 10.2 | E7: 4.9 | F7: 85 | G7: 4.8*3.8 | H7: 8.9535391 | I7: 1.7 | K7: F | L7: FALSE
A8: Prunus domestica | B8: Rosaceae | C8: 25,22 | D8: 33.3 | E8: 7 | F8: 40 | G8: 6*5.5 | H8: 12.95907 | I8: 1.75 | J8: D | L8: FALSE
A9: Ficus carica | B9: Moraceae | C9: 11.4 | D9: 11.4 | E9: 4.4 | F9: 30 | G9: 3.45*3.1 | H9: 7.3042029 | I9: 1.5 | K9: F | L9: TRUE | M9: Almost no leaves
A10: Ficus carica | B10: Moraceae | C10: 10.9 | D10: 10.9 | E10: 4.4 | F10: 30 | G10: 3.45*3.1 | H10: 7.3042029 | I10: 1.8 | K10: F | L10: TRUE | M10: growing with the other fig in the garden
A11: Ginkgo biloba | B11: Ginkgoaceae | C11: 9 | D11: 9 | E11: 3 | F11: 5 | G11: 1*0.9 | H11: 2.120575 | I11: 2 | K11: F | L11: FALSE | M11: almost dead
A12: Thuja plicata | B12: Cupressaceae | C12: 66.3 | D12: 66.3 | E12: 23 | F12: 80 | G12: 7.4*7.4 | H12: 17.435839 | I12: 0.5 | K12: - | L12: FALSE | M12: many trees with similar metrics
A13: Thuja plicata | B13: Cupressaceae | C13: 47.8 | D13: 47.8 | E13: 19.6 | F13: 90 | G13: 7.4*7.5 | H13: 17.671459 | I13: 0.4 | K13: - | L13: FALSE
A14: Thuja plicata | B14: Cupressaceae | C14: 49.4 | D14: 49.4 | E14: 21.3 | F14: 90 | G14: 7.4*7.6 | H14: 17.907078 | I14: 0.5 | K14: - | L14: FALSE
A15: Thuja plicata | B15: Cupressaceae | C15: 59.6 | D15: 59.6 | E15: 21.3 | F15: 90 | G15: 7.4*7.7 | H15: 18.142698 | I15: 0.35 | K15: - | L15: FALSE
A16: Thuja plicata | B16: Cupressaceae | C16: 48.6 | D16: 48.6 | E16: 21.3 | F16: 90 | G16: 7.4*7.8 | H16: 18.378317 | I16: 0.4 | K16: - | L16: FALSE
A17: Thuja plicata | B17: Cupressaceae | C17: 57.8 | D17: 57.8 | E17: 21.3 | F17: 90 | G17: 7.4*7.9 | H17: 18.613936 | I17: 0.6 | K17: - | L17: FALSE
A18: Thuja plicata | B18: Cupressaceae | C18: 45 | D18: 45 | E18: 21.3 | F18: 90 | G18: 7.4*7.10 | H18: 16.728981 | I18: 0.55 | K18: - | L18: FALSE
A19: Thuja plicata | B19: Cupressaceae | C19: 58.6 | D19: 58.6 | E19: 21.3 | F19: 90 | G19: 7.4*7.11 | H19: 16.752543 | I19: 0.5 | K19: - | L19: FALSE
A20: Malus domestica | B20: Rosaceae | C20: 17 | D20: 17 | E20: 4 | F20: 30 | G20: 3.4*3.5 | H20: 8.2466807 | I20: 1.5 | L20: FALSE
A21: Acer palmatum | B21: Aceraceae | C21: 10,14,12,18,15 | D21: 31.46 | E21: 6.2 | F21: 10 | G21: 5*6 | H21: 14.137167 | I21: 1.75 | K21: F | L21: FALSE
A22: Acer griseum | B22: Aceraceae | C22: 10.5 | D22: 10.5 | E22: 6 | F22: 70 | G22: 2.4*3.5 | H22: 8.2466807 | I22: 2 | K22: - | L22: FALSE
A23: Magnolia × soulangeana | B23: Magnoliaceae | C23: 11.7 | D23: 11.7 | E23: 4.5 | F23: 70 | G23: 3.8*2.5 | H23: 5.8904862 | I23: 2 | K23: - | L23: FALSE
A24: Betula pendula | B24: Betulaceae | C24: 29.5 | D24: 29.5 | E24: 14 | F24: 75 | G24: 7*5.5 | H24: 12.95907 | I24: 3 | K24: - | L24: FALSE
A25: Cornus kousa | B25: Cornaceae | C25: 16,10.5 | D25: 19.14 | E25: 5 | F25: 40 | G25: 5.7*4 | H25: 9.424778 | I25: 2 | K25: - | L25: FALSE
A26: Fagus sylvatica | B26: Fagaceae | C26: 35,25 | D26: 43.01 | E26: 11 | F26: 80 | G26: 4*5 | H26: 11.780972 | I26: 1.2 | K26: - | L26: FALSE
A27: Chamaecyparis pisifera | B27: Cupressaceae | C27: 30 | D27: 30 | E27: 11.2 | F27: 40 | G27: 3.5*3.5 | H27: 8.2466807 | I27: 1.2 | K27: - | L27: FALSE
A28: Chamaecyparis pisifera | B28: Cupressaceae | C28: 45 | D28: 45 | E28: 14.6 | F28: 45 | G28: 4.5*4.5 | H28: 10.602875 | I28: 1.2 | K28: - | L28: FALSE
A29: Acer palmatum | B29: Aceraceae | C29: 10,10 | D29: 14.14 | E29: 3.6 | F29: 40 | G29: 1.8*2 | H29: 4.712389 | I29: 1.5 | K29: - | L29: FALSE
A30: Magnolia grandifolia | B30: Magnoliaceae | C30: 15 | D30: 15 | E30: 3.6 | F30: 75 | G30: 3*3 | H30: 7.0685835 | I30: 1.3 | K30: - | L30: TRUE
A31: Cornus florida | B31: Cornaceae | C31: 15 | D31: 15 | E31: 8 | F31: 70 | G31: 4.8*3.5 | H31: 8.2466807 | I31: 4 | L31: FALSE
A32: Thuja plicata | B32: Cupressaceae | C32: 17 | D32: 17 | E32: 8 | F32: 50 | G32: 5*3 | H32: 7.0685835 | I32: 2 | L32: FALSE
A33: Sorbaria sorbifolia | B33: Rosaceae | C33: 11,9,10,9,9 | D33: 21.54 | E33: 7 | F33: 60 | G33: 3.2*2 | H33: 4.712389 | I33: 2 | L33: FALSE
A34: Malus domestica | B34: Rosaceae | C34: 45,20 | D34: 49.24 | E34: 8 | F34: 65 | G34: 5.5*6 | H34: 14.137167 | I34: 0.2 | J34: D | K34: F | L34: FALSE
A35: Prunus serrulata | B35: Rosaceae | C35: 80 | D35: 80 | E35: 16 | F35: 50 | G35: 12*11.3 | H35: 26.624998 | I35: 2.1 | J35: C,D | K35: - | L35: FALSE
A36: Sorbus aucuparia | B36: Rosaceae | C36: 45,40,50 | D36: 78.27 | E36: 14.5 | F36: 65 | G36: 11.5*6.3 | H36: 14.844025 | I36: 2.5 | K36: - | L36: TRUE
A37: Juniperus communis | B37: Cupressaceae | C37: 12 | D37: 12 | E37: 1.5 | F37: 95 | G37: 1*1 | H37: 2.3561945 | I37: 0.4 | K37: - | L37: FALSE
A38: Picea sitchensis | B38: Pinaceae | C38: 100 | D38: 100 | E38: 18.8 | F38: 60 | G38: 9.3*13.3 | H38: 31.337387 | I38: 1.8 | J38: D | K38: - | L38: FALSE
A39: Picea sitchensis | B39: Pinaceae | C39: 85 | D39: 85 | E39: 72.2 | F39: 50 | G39: 4*6 | H39: 14.137167 | I39: 1.5 | J39: C,D | K39: - | L39: FALSE
A40: Ficus carica | B40: Moraceae | C40: 15 | D40: 15 | E40: 3.5 | F40: 30 | G40: 3* 2.5 | H40: 5.8904862 | I40: 1.8 | K40: F | L40: FALSE
...

Sheet Basal_area_Shannon

Sheet Trees_density
A1: species | B1: Density_g_cm3 | C1: Source
A2: Ficus carica | B2: 0.56 | C2: Zanne et al. 2009
A3: Malus domestica | B3: 0.65 | C3: Zanne et al. 2009
A4: Diospyros kaki | B4: 0.78 | C4: Zanne et al. 2009
A5: Vitis vinifera | B5: 0.64 | C5: Zanne et al. 2009
A6: Pyrus communis | B6: 0.67 | C6: Zanne et al. 2009
A7: Prunus domestica | B7: 0.6 | C7: Zanne et al. 2009
A8: Ginkgo biloba | B8: 0.44 | C8: USDA Wood Handbook
A9: Thuja plicata | B9: 0.32 | C9: USDA Wood Handbook
A10: Acer palmatum | B10: 0.53 | C10: Zanne et al. 2009
A11: Acer griseum | B11: 0.62 | C11: Zanne et al. 2009
A12: Magnolia × soulangeana | B12: 0.45 | C12: CIRAD
A13: Betula pendula | B13: 0.57 | C13: Zanne et al. 2009
... A48: Camellia japonica | B48: 0.55 | C48: CIRAD
